Workbook

Sheet Summary
B4: st 1 | C4: ='Income - Stage 1'!D24 -> 462500 | D4: =C4/$C$17 -> 0.31127962
B5: st 2 | C5: ='Income - Stage 1'!D127 -> 475000 | D5: =C5/$C$17 -> 0.31969258
B6: st 3 | D6: =C6/$C$17 -> 0
B7: aust | C7: ='Domestic Holidays'!D29 -> 115568.24 | D7: =C7/$C$17 -> 0.0777817
B8: int | C8: ='International Holidays'!D29 -> 142534.16 | D8: =C8/$C$17 -> 0.095930763
D9: =C9/$C$17 -> 0
D10: =C10/$C$17 -> 0
B11: cp1 | C11: ='Car - P1'!D29 -> 112500 | D11: =C11/$C$17 -> 0.075716664
B12: cp2 | C12: ='Car P2'!D29 -> 96200 | D12: =C12/$C$17 -> 0.06474616
B13: car | C13: =Carvan!D50 -> 81500 | D13: =C13/$C$17 -> 0.054852516
C17: =SUM(C4:C15) -> 1485802.4 | D17: =SUM(D4:D15) -> 1

Sheet Portflio Assuptions

Sheet Income - Stage 1
B2: Stage 1
B3: Calander Year at Stage | C3: 2026
B4: Start year | C4: 1
B5: Stage length | C5: 5
B6: Finish Year | C6: =C3+C5 -> 2031
B7: Partner 1 age | C7: 65
B8: Partner 2 age | C8: 62
B9: Tax Rate (%) | C9: 0.15
B10: Fees % | C10: 0.011
B11: Inflation | C11: 0.03
B13: Portfolio | C13: Conservative | D13: "- this is a pull down menue that automatically fills in the Income % and Growth %"
B14: Portfolio Attributes
B15: income return (%) | C15: 0.045
B16: Growth (%) | C16: 0.005
B18: Calander Year | D18: =C3 -> 2026 | E18: =D18+1 -> 2027 | F18: =E18+1 -> 2028 | G18: =F18+1 -> 2029 | H18: =G18+1 -> 2030 | I18: =H18+1 -> 2031 | J18: =I18+1 -> 2032 | K18: =J18+1 -> 2033 | L18: =K18+1 -> 2034 | M18: =L18+1 -> 2035
B19: Year | D19: 0 | E19: =D19+1 -> 1 | F19: =E19+1 -> 2 | G19: =F19+1 -> 3 | H19: =G19+1 -> 4 | I19: =H19+1 -> 5 | J19: =I19+1 -> 6 | K19: =J19+1 -> 7 | L19: =K19+1 -> 8 | M19: =L19+1 -> 9
B20: Partner 1 age | D20: =C7 -> 65 | E20: =D20+1 -> 66 | F20: =E20+1 -> 67 | G20: =F20+1 -> 68 | H20: =G20+1 -> 69 | I20: =H20+1 -> 70 | J20: =I20+1 -> 71 | K20: =J20+1 -> 72 | L20: =K20+1 -> 73 | M20: =L20+1 -> 74
B21: Partner 2 age | D21: =C8 -> 62 | E21: =D21+1 -> 63 | F21: =E21+1 -> 64 | G21: =F21+1 -> 65 | H21: =G21+1 -> 66 | I21: =H21+1 -> 67 | J21: =I21+1 -> 68 | K21: =J21+1 -> 69 | L21: =K21+1 -> 70 | M21: =L21+1 -> 71
B24: open balance | D24: 462500 | E24: =D34-D42 -> 397415.62 | F24: =E34-E42 -> 327832.28 | G24: =F34-F42 -> 253532.87 | H24: =G34-G42 -> 174291.14 | I24: =H34-H42 -> 89871.33 | J24: =I34-I42 -> 27.754015 | K24: =J34-J42 -> 28.954376 | L24: =K34-K42 -> 30.206653 | M24: =L34-L42 -> 31.513091
B25: income return (%) | D25: =C15 -> 0.045 | E25: =D25 -> 0.045 | F25: =E25 -> 0.045 | G25: =F25 -> 0.045 | H25: =G25 -> 0.045 | I25: =H25 -> 0.045 | J25: =I25 -> 0.045 | K25: =J25 -> 0.045 | L25: =K25 -> 0.045 | M25: =L25 -> 0.045
B26: income return ($) | D26: =D24*D25 -> 20812.5 | E26: =E24*E25 -> 17883.703 | F26: =F24*F25 -> 14752.453 | G26: =G24*G25 -> 11408.979 | H26: =H24*H25 -> 7843.1015 | I26: =I24*I25 -> 4044.2098 | J26: =J24*J25 -> 1.2489307 | K26: =K24*K25 -> 1.3029469 | ... M26: =M24*M25 -> 1.4180891
B27: Tax Rate (%) | D27: =C9 -> 0.15 | E27: =D27 -> 0.15 | F27: =E27 -> 0.15 | G27: =F27 -> 0.15 | H27: =G27 -> 0.15 | I27: =H27 -> 0.15 | J27: =I27 -> 0.15 | K27: =J27 -> 0.15 | L27: =K27 -> 0.15 | M27: =L27 -> 0.15
B28: Tax Rate ($) | D28: =IF((D26*D27)<0,0,(D26*D27)) -> 3121.875 | E28: =IF((E26*E27)<0,0,(E26*E27)) -> 2682.5555 | F28: =IF((F26*F27)<0,0,(F26*F27)) -> 2212.8679 | G28: =IF((G26*G27)<0,0,(G26*G27)) -> 1711.3469 | H28: =IF((H26*H27)<0,0,(H26*H27)) -> 1176.4652 | I28: =IF((I26*I27)<0,0,(I26*I27)) -> 606.63147 | J28: =IF((J26*J27)<0,0,(J26*J27)) -> 0.1873396 | K28: =IF((K26*K27)<0,0,(K26*K27)) -> 0.19544204 | ... M28: =IF((M26*M27)<0,0,(M26*M27)) -> 0.21271336 | V28: =SUM(D28:N28) -> 11512.541
B29: Income after tax | D29: =IF((D26-D28)<0,0,(D26-D28)) -> 17690.625 | E29: =IF((E26-E28)<0,0,(E26-E28)) -> 15201.148 | F29: =IF((F26-F28)<0,0,(F26-F28)) -> 12539.585 | G29: =IF((G26-G28)<0,0,(G26-G28)) -> 9697.6323 | H29: =IF((H26-H28)<0,0,(H26-H28)) -> 6666.6363 | I29: =IF((I26-I28)<0,0,(I26-I28)) -> 3437.5784 | J29: =IF((J26-J28)<0,0,(J26-J28)) -> 1.0615911 | K29: =IF((K26-K28)<0,0,(K26-K28)) -> 1.1075049 | ... M29: =IF((M26-M28)<0,0,(M26-M28)) -> 1.2053757 | V29: =SUM(D29:N29) -> 65237.734
B31: Growth (%) | D31: =C16 -> 0.005 | E31: =D31 -> 0.005 | F31: =E31 -> 0.005 | G31: =F31 -> 0.005 | H31: =G31 -> 0.005 | I31: =H31 -> 0.005 | J31: =I31 -> 0.005 | K31: =J31 -> 0.005 | L31: =K31 -> 0.005 | M31: =L31 -> 0.005
B32: Growth ($) | D32: =IF((D31*D24)<0,0,(D31*D24)) -> 2312.5 | E32: =IF((E31*E24)<0,0,(E31*E24)) -> 1987.0781 | F32: =IF((F31*F24)<0,0,(F31*F24)) -> 1639.1614 | G32: =IF((G31*G24)<0,0,(G31*G24)) -> 1267.6643 | H32: =IF((H31*H24)<0,0,(H31*H24)) -> 871.45572 | I32: =IF((I31*I24)<0,0,(I31*I24)) -> 449.35665 | J32: =IF((J31*J24)<0,0,(J31*J24)) -> 0.13877008 | K32: =IF((K31*K24)<0,0,(K31*K24)) -> 0.14477188 | ... M32: =IF((M31*M24)<0,0,(M31*M24)) -> 0.15756545 | V32: =SUM(D32:M32) -> 8527.8084
B34: Closing Balance | D34: =D24+D29+D32 -> 482503.12 | E34: =E24+E29+E32 -> 414603.85 | F34: =F24+F29+F32 -> 342011.02 | G34: =G24+G29+G32 -> 264498.17 | H34: =H24+H29+H32 -> 181829.24 | I34: =I24+I29+I32 -> 93758.265 | J34: =J24+J29+J32 -> 28.954376 | K34: =K24+K29+K32 -> 30.206653 | ... M34: =M24+M29+M32 -> 32.876032
B36: income needed ex fees | D36: 80000 | E36: =D36*(1+D37) -> 82400 | F36: =E36*(1+E37) -> 84872 | G36: =F36*(1+F37) -> 87418.16 | H36: =G36*(1+G37) -> 90040.705 | I36: =H36*(1+H37) -> 92741.926 | J36: =I36*(1+I37) -> 95524.184 | K36: =J36*(1+J37) -> 98389.909 | L36: =K36*(1+K37) -> 101341.61 | M36: =L36*(1+L37) -> 104381.85
B37: Inflation assumed | D37: =C11 -> 0.03 | E37: =D37 -> 0.03 | F37: =E37 -> 0.03 | G37: =F37 -> 0.03 | H37: =G37 -> 0.03 | I37: =H37 -> 0.03 | J37: =I37 -> 0.03 | K37: =J37 -> 0.03 | L37: =K37 -> 0.03 | M37: =L37 -> 0.03
B39: Fees (%) | D39: =C10 -> 0.011 | E39: =D39 -> 0.011 | F39: =E39 -> 0.011 | G39: =F39 -> 0.011 | H39: =G39 -> 0.011 | I39: =H39 -> 0.011 | J39: =I39 -> 0.011 | K39: =J39 -> 0.011 | L39: =K39 -> 0.011 | M39: =L39 -> 0.011
B40: Fees ($) | D40: =IF((D39*D24)<0,0,(D39*D24)) -> 5087.5 | E40: =IF((E39*E24)<0,0,(E39*E24)) -> 4371.5719 | F40: =IF((F39*F24)<0,0,(F39*F24)) -> 3606.1551 | G40: =IF((G39*G24)<0,0,(G39*G24)) -> 2788.8616 | H40: =IF((H39*H24)<0,0,(H39*H24)) -> 1917.2026 | I40: =IF((I39*I24)<0,0,(I39*I24)) -> 988.58463 | J40: =IF((J39*J24)<0,0,(J39*J24)) -> 0.30529417 | K40: =IF((K39*K24)<0,0,(K39*K24)) -> 0.31849814 | ... M40: =IF((M39*M24)<0,0,(M39*M24)) -> 0.346644 | V40: =SUM(D40:N40) -> 18761.178 | W40: =V40/V42 -> 0.034987011
B42: income needed inclusive of fees | D42: =IF(D19<=$C$5,(D36+D40),0) -> 85087.5 | E42: =IF(E19<=$C$5,(E36+E40),0) -> 86771.572 | F42: =IF(F19<=$C$5,(F36+F40),0) -> 88478.155 | G42: =IF(G19<=$C$5,(G36+G40),0) -> 90207.022 | H42: =IF(H19<=$C$5,(H36+H40),0) -> 91957.907 | I42: =IF(I19<=$C$5,(I36+I40),0) -> 93730.511 | J42: =IF(J19<=$C$5,(J36+J40),0) -> 0 | K42: =IF(K19<=$C$5,(K36+K40),0) -> 0 | ... M42: =IF(M19<=$C$5,(M36+M40),0) -> 0 | V42: =SUM(D42:N42) -> 536232.67
B44: Finial Closing balance | D44: =D34-D36 -> 402503.12 | E44: =E34-E36 -> 332203.85 | F44: =F34-F36 -> 257139.02 | G44: =G34-G36 -> 177080.01 | H44: =H34-H36 -> 91788.532 | I44: =I34-I36 -> 1016.3386 | J44: =J34-J36 -> -95495.229 | K44: =K34-K36 -> -98359.703 | ... M44: =M34-M36 -> -104348.98
B47: Stage 2
B48: Calander Year at Stage | C48: =(C3+C5)+1 -> 2032
B49: Start year | C49: =C48-C3 -> 6
B50: Stage length | C50: 10
B51: Finish Year | C51: =C48+C50 -> 2042
B52: The year that needs to be iqual to $0 is | C52: =C51+1 -> 2043
B54: Partner 1 age at start of Stage | C54: =C7+C5 -> 70
...

Sheet Income - Stage 2

Sheet Income - Stage 3

Sheet Car - P1
B1: Car for Partner 1
B2: Calander Year at Stage | C2: ='Income - Stage 1'!C3 -> 2026
B3: Start year | C3: ='Income - Stage 1'!C4 -> 1
B4: Stage length | C4: 26
B5: Finish Year | C5: =C2+C4 -> 2052
B6: The year that needs to be iqual to $0 is | C6: =C5+1 -> 2053
B8: Partner 1 age at start of Stage | C8: ='Income - Stage 1'!C7 -> 65
B9: Partner 1 age at END of Stage | C9: =C8+C4 -> 91
B11: Partner 2 age at stage of stage | C11: ='Income - Stage 1'!C8 -> 62
B12: Partner 2 age at END of Stage | C12: =C11+C4 -> 88
B14: Tax Rate (%) | C14: 0.15
B15: Fees % | C15: 0.011
B16: Inflation | C16: 0.03
B18: Portfolio | C18: Balanced | D18: "- this is a pull down menue that automatically fills in the Income % and Growth %"
B19: Portfolio Attributes
B20: income return (%) | C20: 0.035
B21: Growth (%) | C21: 0.045
B23: Calander Year | D23: =C2 -> 2026 | E23: =D23+1 -> 2027 | F23: =E23+1 -> 2028 | G23: =F23+1 -> 2029 | H23: =G23+1 -> 2030 | I23: =H23+1 -> 2031 | J23: =I23+1 -> 2032 | K23: =J23+1 -> 2033 | L23: =K23+1 -> 2034 | ... AI23: =AH23+1 -> 2057
B24: Year | D24: =C3 -> 1 | E24: =D24+1 -> 2 | F24: =E24+1 -> 3 | G24: =F24+1 -> 4 | H24: =G24+1 -> 5 | I24: =H24+1 -> 6 | J24: =I24+1 -> 7 | K24: =J24+1 -> 8 | L24: =K24+1 -> 9 | ... AI24: =AH24+1 -> 32
B25: Partner 1 age | D25: =C8 -> 65 | E25: =D25+1 -> 66 | F25: =E25+1 -> 67 | G25: =F25+1 -> 68 | H25: =G25+1 -> 69 | I25: =H25+1 -> 70 | J25: =I25+1 -> 71 | K25: =J25+1 -> 72 | L25: =K25+1 -> 73 | ... AI25: =AH25+1 -> 96
B26: Partner 2 age | D26: =C11 -> 62 | E26: =D26+1 -> 63 | F26: =E26+1 -> 64 | G26: =F26+1 -> 65 | H26: =G26+1 -> 66 | I26: =H26+1 -> 67 | J26: =I26+1 -> 68 | K26: =J26+1 -> 69 | L26: =K26+1 -> 70 | ... AI26: =AH26+1 -> 93
B29: open balance | D29: 112500 | E29: =D58 -> 67609.375 | F29: =E58 -> 69363.176 | G29: =F58 -> 71248.073 | H29: =G58 -> 73273.867 | I29: =H58 -> 75451.088 | J29: =I58 -> 77791.057 | K29: =J58 -> 80305.939 | L29: =K58 -> 83008.807 | ... AI29: =AH58 -> 421.08392
B30: income return (%) | D30: =C20 -> 0.035 | E30: =D30 -> 0.035 | F30: =E30 -> 0.035 | G30: =F30 -> 0.035 | H30: =G30 -> 0.035 | I30: =H30 -> 0.035 | J30: =I30 -> 0.035 | K30: =J30 -> 0.035 | L30: =K30 -> 0.035 | ... AI30: =AH30 -> 0.035
B31: income return ($) | D31: =D29*D30 -> 3937.5 | E31: =E29*E30 -> 2366.3281 | F31: =F29*F30 -> 2427.7112 | G31: =G29*G30 -> 2493.6826 | H31: =H29*H30 -> 2564.5853 | I31: =I29*I30 -> 2640.7881 | J31: =J29*J30 -> 2722.687 | K31: =K29*K30 -> 2810.7078 | ... AI31: =AI29*AI30 -> 14.737937
B32: Tax Rate (%) | D32: =C14 -> 0.15 | E32: =D32 -> 0.15 | F32: =E32 -> 0.15 | G32: =F32 -> 0.15 | H32: =G32 -> 0.15 | I32: =H32 -> 0.15 | J32: =I32 -> 0.15 | K32: =J32 -> 0.15 | L32: =K32 -> 0.15 | ... AI32: =AH32 -> 0.15
B33: Tax Rate ($) | D33: =IF((D31*D32)<0,0,(D31*D32)) -> 590.625 | E33: =IF((E31*E32)<0,0,(E31*E32)) -> 354.94922 | F33: =IF((F31*F32)<0,0,(F31*F32)) -> 364.15667 | G33: =IF((G31*G32)<0,0,(G31*G32)) -> 374.05238 | H33: =IF((H31*H32)<0,0,(H31*H32)) -> 384.6878 | I33: =IF((I31*I32)<0,0,(I31*I32)) -> 396.11821 | J33: =IF((J31*J32)<0,0,(J31*J32)) -> 408.40305 | K33: =IF((K31*K32)<0,0,(K31*K32)) -> 421.60618 | ... AI33: =IF((AI31*AI32)<0,0,(AI31*AI32)) -> 2.2106906
B34: Income after tax | D34: =IF((D31-D33)<0,0,(D31-D33)) -> 3346.875 | E34: =IF((E31-E33)<0,0,(E31-E33)) -> 2011.3789 | F34: =IF((F31-F33)<0,0,(F31-F33)) -> 2063.5545 | G34: =IF((G31-G33)<0,0,(G31-G33)) -> 2119.6302 | H34: =IF((H31-H33)<0,0,(H31-H33)) -> 2179.8975 | I34: =IF((I31-I33)<0,0,(I31-I33)) -> 2244.6699 | J34: =IF((J31-J33)<0,0,(J31-J33)) -> 2314.2839 | K34: =IF((K31-K33)<0,0,(K31-K33)) -> 2389.1017 | ... AI34: =IF((AI31-AI33)<0,0,(AI31-AI33)) -> 12.527247
B36: Growth (%) | D36: =C21 -> 0.045 | E36: =D36 -> 0.045 | F36: =E36 -> 0.045 | G36: =F36 -> 0.045 | H36: =G36 -> 0.045 | I36: =H36 -> 0.045 | J36: =I36 -> 0.045 | K36: =J36 -> 0.045 | L36: =K36 -> 0.045 | ... AI36: =AH36 -> 0.045
B37: Growth ($) | D37: =IF((D36*D29)<0,0,(D36*D29)) -> 5062.5 | E37: =IF((E36*E29)<0,0,(E36*E29)) -> 3042.4219 | F37: =IF((F36*F29)<0,0,(F36*F29)) -> 3121.3429 | G37: =IF((G36*G29)<0,0,(G36*G29)) -> 3206.1633 | H37: =IF((H36*H29)<0,0,(H36*H29)) -> 3297.324 | I37: =IF((I36*I29)<0,0,(I36*I29)) -> 3395.299 | J37: =IF((J36*J29)<0,0,(J36*J29)) -> 3500.5976 | K37: =IF((K36*K29)<0,0,(K36*K29)) -> 3613.7672 | ... AI37: =IF((AI36*AI29)<0,0,(AI36*AI29)) -> 18.948777
B39: Closing Balance | D39: =D29+D34+D37 -> 120909.38 | E39: =E29+E34+E37 -> 72663.176 | F39: =F29+F34+F37 -> 74548.073 | G39: =G29+G34+G37 -> 76573.867 | H39: =H29+H34+H37 -> 78751.088 | I39: =I29+I34+I37 -> 81091.057 | J39: =J29+J34+J37 -> 83605.939 | K39: =K29+K34+K37 -> 86308.807 | ... AI39: =AI29+AI34+AI37 -> 452.55995
B41: Capital Needed - Purchase Price | D41: 50000 | E41: 0 | F41: 0 | G41: 0 | H41: 0 | I41: 0 | J41: 0 | K41: 0 | L41: 0 | M41: 50000 | N41: 0 | O41: 0 | P41: 0 | Q41: 0 | R41: 0 | S41: 0 | T41: 0 | U41: 0 | V41: 50000 | W41: 0 | X41: 0 | Y41: 0 | Z41: 0 | AA41: 0 | AB41: 0 | AC41: 0 | AD41: 0 | AE41: 0 | AF41: 0 | AG41: 0 | AH41: 0 | AI41: 0
B42: Trade in Value | D42: 0 | M42: 10000 | V42: 10000 | AC42: 0 | AD42: 10000
B43: Holding Cost
B44: Rego | C44: 500
B45: Insurance | C45: 1200
B46: Maintenance | C46: 1000
B47: Services | C47: 600
B48: Hollding Costs - Total | C48: =SUM(C44:C47) -> 3300 | D48: =IF(D23<$C$6,C48,0) -> 3300 | E48: =IF(E23<$C$6,D48,0) -> 3300 | F48: =IF(F23<$C$6,E48,0) -> 3300 | G48: =IF(G23<$C$6,F48,0) -> 3300 | H48: =IF(H23<$C$6,G48,0) -> 3300 | I48: =IF(I23<$C$6,H48,0) -> 3300 | J48: =IF(J23<$C$6,I48,0) -> 3300 | K48: =IF(K23<$C$6,J48,0) -> 3300 | ... AI48: =IF(AI23<$C$6,AH48,0) -> 0
B50: income needed ex fees | D50: =D41-D42+D48 -> 53300 | E50: =E41-E42+E48 -> 3300 | F50: =F41-F42+F48 -> 3300 | G50: =G41-G42+G48 -> 3300 | H50: =H41-H42+H48 -> 3300 | I50: =I41-I42+I48 -> 3300 | J50: =J41-J42+J48 -> 3300 | K50: =K41-K42+K48 -> 3300 | ... AI50: =AI41-AI42+AI48 -> 0
B51: Inflation assumed | D51: =C16 -> 0.03 | E51: =D51 -> 0.03 | F51: =E51 -> 0.03 | G51: =F51 -> 0.03 | H51: =G51 -> 0.03 | I51: =H51 -> 0.03 | J51: =I51 -> 0.03 | K51: =J51 -> 0.03 | L51: =K51 -> 0.03 | ... AI51: =AH51 -> 0.03
...

Sheet Car P2
B1: Car for Partner 2
B2: Calander Year at Stage | C2: ='Income - Stage 1'!C3 -> 2026
B3: Start year | C3: ='Income - Stage 1'!C4 -> 1
B4: Stage length | C4: 19
B5: Finish Year | C5: =C2+C4 -> 2045
B6: The year that needs to be iqual to $0 is | C6: =C5+1 -> 2046
B8: Partner 1 age at start of Stage | C8: ='Income - Stage 1'!C7 -> 65
B9: Partner 1 age at END of Stage | C9: =C8+C4 -> 84
B11: Partner 2 age at stage of stage | C11: ='Income - Stage 1'!C8 -> 62
B12: Partner 2 age at END of Stage | C12: =C11+C4 -> 81
B14: Tax Rate (%) | C14: 0.15
B15: Fees % | C15: 0.011
B16: Inflation | C16: 0.03
B18: Portfolio | C18: Balanced | D18: "- this is a pull down menue that automatically fills in the Income % and Growth %"
B19: Portfolio Attributes
B20: income return (%) | C20: 0.035
B21: Growth (%) | C21: 0.045
B23: Calander Year | D23: =C2 -> 2026 | E23: =D23+1 -> 2027 | F23: =E23+1 -> 2028 | G23: =F23+1 -> 2029 | H23: =G23+1 -> 2030 | I23: =H23+1 -> 2031 | J23: =I23+1 -> 2032 | K23: =J23+1 -> 2033 | L23: =K23+1 -> 2034 | ... AI23: =AH23+1 -> 2057
B24: Year | D24: =C3 -> 1 | E24: =D24+1 -> 2 | F24: =E24+1 -> 3 | G24: =F24+1 -> 4 | H24: =G24+1 -> 5 | I24: =H24+1 -> 6 | J24: =I24+1 -> 7 | K24: =J24+1 -> 8 | L24: =K24+1 -> 9 | ... AI24: =AH24+1 -> 32
B25: Partner 1 age | D25: =C8 -> 65 | E25: =D25+1 -> 66 | F25: =E25+1 -> 67 | G25: =F25+1 -> 68 | H25: =G25+1 -> 69 | I25: =H25+1 -> 70 | J25: =I25+1 -> 71 | K25: =J25+1 -> 72 | L25: =K25+1 -> 73 | ... AI25: =AH25+1 -> 96
B26: Partner 2 age | D26: =C11 -> 62 | E26: =D26+1 -> 63 | F26: =E26+1 -> 64 | G26: =F26+1 -> 65 | H26: =G26+1 -> 66 | I26: =H26+1 -> 67 | J26: =I26+1 -> 68 | K26: =J26+1 -> 69 | L26: =K26+1 -> 70 | ... AI26: =AH26+1 -> 93
B29: open balance | D29: 96200 | E29: =D58 -> 50090.95 | F29: =E58 -> 50535.249 | G29: =F58 -> 51012.758 | H29: =G58 -> 51525.962 | I29: =H58 -> 52077.528 | J29: =I58 -> 52670.323 | K29: =J58 -> 53307.43 | L29: =K58 -> 53992.16 | ... AI29: =AH58 -> -3161.4673
B30: income return (%) | D30: =C20 -> 0.035 | E30: =D30 -> 0.035 | F30: =E30 -> 0.035 | G30: =F30 -> 0.035 | H30: =G30 -> 0.035 | I30: =H30 -> 0.035 | J30: =I30 -> 0.035 | K30: =J30 -> 0.035 | L30: =K30 -> 0.035 | ... AI30: =AH30 -> 0.035
B31: income return ($) | D31: =D29*D30 -> 3367 | E31: =E29*E30 -> 1753.1833 | F31: =F29*F30 -> 1768.7337 | G31: =G29*G30 -> 1785.4465 | H31: =H29*H30 -> 1803.4087 | I31: =I29*I30 -> 1822.7135 | J31: =J29*J30 -> 1843.4613 | K31: =K29*K30 -> 1865.76 | ... AI31: =AI29*AI30 -> -110.65136
B32: Tax Rate (%) | D32: =C14 -> 0.15 | E32: =D32 -> 0.15 | F32: =E32 -> 0.15 | G32: =F32 -> 0.15 | H32: =G32 -> 0.15 | I32: =H32 -> 0.15 | J32: =I32 -> 0.15 | K32: =J32 -> 0.15 | L32: =K32 -> 0.15 | ... AI32: =AH32 -> 0.15
B33: Tax Rate ($) | D33: =IF((D31*D32)<0,0,(D31*D32)) -> 505.05 | E33: =IF((E31*E32)<0,0,(E31*E32)) -> 262.97749 | F33: =IF((F31*F32)<0,0,(F31*F32)) -> 265.31005 | G33: =IF((G31*G32)<0,0,(G31*G32)) -> 267.81698 | H33: =IF((H31*H32)<0,0,(H31*H32)) -> 270.5113 | I33: =IF((I31*I32)<0,0,(I31*I32)) -> 273.40702 | J33: =IF((J31*J32)<0,0,(J31*J32)) -> 276.5192 | K33: =IF((K31*K32)<0,0,(K31*K32)) -> 279.864 | ... AI33: =IF((AI31*AI32)<0,0,(AI31*AI32)) -> 0
B34: Income after tax | D34: =IF((D31-D33)<0,0,(D31-D33)) -> 2861.95 | E34: =IF((E31-E33)<0,0,(E31-E33)) -> 1490.2058 | F34: =IF((F31-F33)<0,0,(F31-F33)) -> 1503.4236 | G34: =IF((G31-G33)<0,0,(G31-G33)) -> 1517.6296 | H34: =IF((H31-H33)<0,0,(H31-H33)) -> 1532.8974 | I34: =IF((I31-I33)<0,0,(I31-I33)) -> 1549.3064 | J34: =IF((J31-J33)<0,0,(J31-J33)) -> 1566.9421 | K34: =IF((K31-K33)<0,0,(K31-K33)) -> 1585.896 | ... AI34: =IF((AI31-AI33)<0,0,(AI31-AI33)) -> 0
B36: Growth (%) | D36: =C21 -> 0.045 | E36: =D36 -> 0.045 | F36: =E36 -> 0.045 | G36: =F36 -> 0.045 | H36: =G36 -> 0.045 | I36: =H36 -> 0.045 | J36: =I36 -> 0.045 | K36: =J36 -> 0.045 | L36: =K36 -> 0.045 | ... AI36: =AH36 -> 0.045
B37: Growth ($) | D37: =IF((D36*D29)<0,0,(D36*D29)) -> 4329 | E37: =IF((E36*E29)<0,0,(E36*E29)) -> 2254.0927 | F37: =IF((F36*F29)<0,0,(F36*F29)) -> 2274.0862 | G37: =IF((G36*G29)<0,0,(G36*G29)) -> 2295.5741 | H37: =IF((H36*H29)<0,0,(H36*H29)) -> 2318.6683 | I37: =IF((I36*I29)<0,0,(I36*I29)) -> 2343.4887 | J37: =IF((J36*J29)<0,0,(J36*J29)) -> 2370.1645 | K37: =IF((K36*K29)<0,0,(K36*K29)) -> 2398.8343 | ... AI37: =IF((AI36*AI29)<0,0,(AI36*AI29)) -> 0
B39: Closing Balance | D39: =D29+D34+D37 -> 103390.95 | E39: =E29+E34+E37 -> 53835.249 | F39: =F29+F34+F37 -> 54312.758 | G39: =G29+G34+G37 -> 54825.962 | H39: =H29+H34+H37 -> 55377.528 | I39: =I29+I34+I37 -> 55970.323 | J39: =J29+J34+J37 -> 56607.43 | K39: =K29+K34+K37 -> 57292.16 | ... AI39: =AI29+AI34+AI37 -> -3161.4673
B41: Capital Needed - Purchase Price | D41: 50000 | E41: 0 | F41: 0 | G41: 0 | H41: 0 | I41: 0 | J41: 0 | K41: 0 | L41: 0 | M41: 50000 | N41: 0 | O41: 0 | P41: 0 | Q41: 0 | R41: 0 | S41: 0 | T41: 0 | U41: 0 | V41: 0 | W41: 0 | X41: 0 | Y41: 0 | Z41: 0 | AA41: 0 | AB41: 0 | AC41: 0 | AD41: 0 | AE41: 0 | AF41: 0 | AG41: 0 | AH41: 0 | AI41: 0
B42: Trade in Value | D42: 0 | M42: 10000 | V42: 10000 | AC42: 0
B43: Holding Cost
B44: Rego | C44: 500
B45: Insurance | C45: 1200
B46: Maintenance | C46: 1000
B47: Services | C47: 600
B48: Hollding Costs - Total | C48: =SUM(C44:C47) -> 3300 | D48: =IF(D23<$C$6,C48,0) -> 3300 | E48: =IF(E23<$C$6,D48,0) -> 3300 | F48: =IF(F23<$C$6,E48,0) -> 3300 | G48: =IF(G23<$C$6,F48,0) -> 3300 | H48: =IF(H23<$C$6,G48,0) -> 3300 | I48: =IF(I23<$C$6,H48,0) -> 3300 | J48: =IF(J23<$C$6,I48,0) -> 3300 | K48: =IF(K23<$C$6,J48,0) -> 3300 | ... AI48: =IF(AI23<$C$6,AH48,0) -> 0
B50: income needed ex fees | D50: =D41-D42+D48 -> 53300 | E50: =E41-E42+E48 -> 3300 | F50: =F41-F42+F48 -> 3300 | G50: =G41-G42+G48 -> 3300 | H50: =H41-H42+H48 -> 3300 | I50: =I41-I42+I48 -> 3300 | J50: =J41-J42+J48 -> 3300 | K50: =K41-K42+K48 -> 3300 | ... AI50: =AI41-AI42+AI48 -> 0
B51: Inflation assumed | D51: =C16 -> 0.03 | E51: =D51 -> 0.03 | F51: =E51 -> 0.03 | G51: =F51 -> 0.03 | H51: =G51 -> 0.03 | I51: =H51 -> 0.03 | J51: =I51 -> 0.03 | K51: =J51 -> 0.03 | L51: =K51 -> 0.03 | ... AI51: =AH51 -> 0.03
...

Sheet Carvan
B1: Caravan
B2: Calander Year at Stage | C2: ='Income - Stage 1'!C3 -> 2026
B3: Start year | C3: ='Income - Stage 1'!C4 -> 1
B4: Stage length | C4: 19
B5: Finish Year | C5: =C2+C4 -> 2045
B6: The year that needs to be iqual to $0 is | C6: =C5+1 -> 2046
B8: Partner 1 age at start of Stage | C8: ='Income - Stage 1'!C7 -> 65
B9: Partner 1 age at END of Stage | C9: =C8+C4 -> 84
B11: Partner 2 age at stage of stage | C11: ='Income - Stage 1'!C8 -> 62
B12: Partner 2 age at END of Stage | C12: =C11+C4 -> 81
B14: Tax Rate (%) | C14: 0
B15: Fees % | C15: 0.011
B16: Inflation | C16: 0.03
B18: Portfolio | C18: Balanced | D18: "- this is a pull down menue that automatically fills in the Income % and Growth %"
B19: Portfolio Attributes
B20: income return (%) | C20: 0.035
B21: Growth (%) | C21: 0.045
B23: Calander Year | D23: =C2 -> 2026 | E23: =D23+1 -> 2027 | F23: =E23+1 -> 2028 | G23: =F23+1 -> 2029 | H23: =G23+1 -> 2030 | I23: =H23+1 -> 2031 | J23: =I23+1 -> 2032 | K23: =J23+1 -> 2033 | L23: =K23+1 -> 2034 | ... AI23: =AH23+1 -> 2057
B24: Year | D24: =C3 -> 1 | E24: =D24+1 -> 2 | F24: =E24+1 -> 3 | G24: =F24+1 -> 4 | H24: =G24+1 -> 5 | I24: =H24+1 -> 6 | J24: =I24+1 -> 7 | K24: =J24+1 -> 8 | L24: =K24+1 -> 9 | ... AI24: =AH24+1 -> 32
B25: Partner 1 age | D25: =C8 -> 65 | E25: =D25+1 -> 66 | F25: =E25+1 -> 67 | G25: =F25+1 -> 68 | H25: =G25+1 -> 69 | I25: =H25+1 -> 70 | J25: =I25+1 -> 71 | K25: =J25+1 -> 72 | L25: =K25+1 -> 73 | ... AI25: =AH25+1 -> 96
B26: Partner 2 age | D26: =C11 -> 62 | E26: =D26+1 -> 63 | F26: =E26+1 -> 64 | G26: =F26+1 -> 65 | H26: =G26+1 -> 66 | I26: =H26+1 -> 67 | J26: =I26+1 -> 68 | K26: =J26+1 -> 69 | L26: =K26+1 -> 70 | ... AI26: =AH26+1 -> 93
B29: open balance | D29: 88801.295 | E29: =D58 -> 14405.399 | F29: =E58 -> 14057.831 | G29: =F58 -> 13682.457 | H29: =G58 -> 13277.054 | I29: =H58 -> 12839.218 | J29: =I58 -> 12366.355 | K29: =J58 -> 11855.664 | L29: =K58 -> 11304.117 | ... AI29: =AH58 -> -9.5496944e-12
B30: income return (%) | D30: =C20 -> 0.035 | E30: =D30 -> 0.035 | F30: =E30 -> 0.035 | G30: =F30 -> 0.035 | H30: =G30 -> 0.035 | I30: =H30 -> 0.035 | J30: =I30 -> 0.035 | K30: =J30 -> 0.035 | L30: =K30 -> 0.035 | ... AI30: =AH30 -> 0.035
B31: income return ($) | D31: =D29*D30 -> 3108.0453 | E31: =E29*E30 -> 504.18896 | F31: =F29*F30 -> 492.02407 | G31: =G29*G30 -> 478.886 | H31: =H29*H30 -> 464.69688 | I31: =I29*I30 -> 449.37263 | J31: =J29*J30 -> 432.82244 | K31: =K29*K30 -> 414.94824 | ... AI31: =AI29*AI30 -> -3.342393e-13
B32: Tax Rate (%) | D32: =C14 -> 0 | E32: =D32 -> 0 | F32: =E32 -> 0 | G32: =F32 -> 0 | H32: =G32 -> 0 | I32: =H32 -> 0 | J32: =I32 -> 0 | K32: =J32 -> 0 | L32: =K32 -> 0 | ... AI32: =AH32 -> 0
B33: Tax Rate ($) | D33: =IF((D31*D32)<0,0,(D31*D32)) -> 0 | E33: =IF((E31*E32)<0,0,(E31*E32)) -> 0 | F33: =IF((F31*F32)<0,0,(F31*F32)) -> 0 | G33: =IF((G31*G32)<0,0,(G31*G32)) -> 0 | H33: =IF((H31*H32)<0,0,(H31*H32)) -> 0 | I33: =IF((I31*I32)<0,0,(I31*I32)) -> 0 | J33: =IF((J31*J32)<0,0,(J31*J32)) -> 0 | K33: =IF((K31*K32)<0,0,(K31*K32)) -> 0 | ... AI33: =IF((AI31*AI32)<0,0,(AI31*AI32)) -> 0
B34: Income after tax | D34: =IF((D31-D33)<0,0,(D31-D33)) -> 3108.0453 | E34: =IF((E31-E33)<0,0,(E31-E33)) -> 504.18896 | F34: =IF((F31-F33)<0,0,(F31-F33)) -> 492.02407 | G34: =IF((G31-G33)<0,0,(G31-G33)) -> 478.886 | H34: =IF((H31-H33)<0,0,(H31-H33)) -> 464.69688 | I34: =IF((I31-I33)<0,0,(I31-I33)) -> 449.37263 | J34: =IF((J31-J33)<0,0,(J31-J33)) -> 432.82244 | K34: =IF((K31-K33)<0,0,(K31-K33)) -> 414.94824 | ... AI34: =IF((AI31-AI33)<0,0,(AI31-AI33)) -> 0
B36: Growth (%) | D36: =C21 -> 0.045 | E36: =D36 -> 0.045 | F36: =E36 -> 0.045 | G36: =F36 -> 0.045 | H36: =G36 -> 0.045 | I36: =H36 -> 0.045 | J36: =I36 -> 0.045 | K36: =J36 -> 0.045 | L36: =K36 -> 0.045 | ... AI36: =AH36 -> 0.045
B37: Growth ($) | D37: =IF((D36*D29)<0,0,(D36*D29)) -> 3996.0583 | E37: =IF((E36*E29)<0,0,(E36*E29)) -> 648.24295 | F37: =IF((F36*F29)<0,0,(F36*F29)) -> 632.60238 | G37: =IF((G36*G29)<0,0,(G36*G29)) -> 615.71057 | H37: =IF((H36*H29)<0,0,(H36*H29)) -> 597.46742 | I37: =IF((I36*I29)<0,0,(I36*I29)) -> 577.76481 | J37: =IF((J36*J29)<0,0,(J36*J29)) -> 556.486 | K37: =IF((K36*K29)<0,0,(K36*K29)) -> 533.50488 | ... AI37: =IF((AI36*AI29)<0,0,(AI36*AI29)) -> 0
B39: Closing Balance | D39: =D29+D34+D37 -> 95905.399 | E39: =E29+E34+E37 -> 15557.831 | F39: =F29+F34+F37 -> 15182.457 | G39: =G29+G34+G37 -> 14777.054 | H39: =H29+H34+H37 -> 14339.218 | I39: =I29+I34+I37 -> 13866.355 | J39: =J29+J34+J37 -> 13355.664 | K39: =K29+K34+K37 -> 12804.117 | ... AI39: =AI29+AI34+AI37 -> -9.5496944e-12
B41: Capital Needed - Purchase Price | D41: 80000 | E41: 0 | F41: 0 | G41: 0 | H41: 0 | I41: 0 | J41: 0 | K41: 0 | L41: 0 | M41: 0 | N41: 0 | O41: 0 | P41: 0 | Q41: 0 | R41: 0 | S41: 0 | T41: 0 | U41: 0 | V41: 0 | W41: 0 | X41: 0 | Y41: 0 | Z41: 0 | AA41: 0 | AB41: 0 | AC41: 0 | AD41: 0 | AE41: 0 | AF41: 0 | AG41: 0 | AH41: 0 | AI41: 0
B42: Trade in Value | D42: 0 | M42: 0 | V42: 0 | AC42: 0
B43: Holding Cost
B44: Rego | C44: 200
B45: Insurance | C45: 800
B46: Maintenance | C46: 300
B47: Services | C47: 200
B48: Hollding Costs - Total | C48: =SUM(C44:C47) -> 1500 | D48: =IF(D23<$C$6,C48,0) -> 1500 | E48: =IF(E23<$C$6,D48,0) -> 1500 | F48: =IF(F23<$C$6,E48,0) -> 1500 | G48: =IF(G23<$C$6,F48,0) -> 1500 | H48: =IF(H23<$C$6,G48,0) -> 1500 | I48: =IF(I23<$C$6,H48,0) -> 1500 | J48: =IF(J23<$C$6,I48,0) -> 1500 | K48: =IF(K23<$C$6,J48,0) -> 1500 | ... AI48: =IF(AI23<$C$6,AH48,0) -> 0
B50: income needed ex fees | D50: =D41-D42+D48 -> 81500 | E50: =E41-E42+E48 -> 1500 | F50: =F41-F42+F48 -> 1500 | G50: =G41-G42+G48 -> 1500 | H50: =H41-H42+H48 -> 1500 | I50: =I41-I42+I48 -> 1500 | J50: =J41-J42+J48 -> 1500 | K50: =K41-K42+K48 -> 1500 | ... AI50: =AI41-AI42+AI48 -> 0
B51: Inflation assumed | D51: =C16 -> 0.03 | E51: =D51 -> 0.03 | F51: =E51 -> 0.03 | G51: =F51 -> 0.03 | H51: =G51 -> 0.03 | I51: =H51 -> 0.03 | J51: =I51 -> 0.03 | K51: =J51 -> 0.03 | L51: =K51 -> 0.03 | ... AI51: =AH51 -> 0.03
...

Sheet Boat

Sheet Domestic Holidays
B1: Car for Partner 2
B2: Calander Year at Stage | C2: ='Income - Stage 1'!C3 -> 2026
B3: Start year | C3: ='Income - Stage 1'!C4 -> 1
B4: Stage length | C4: 23
B5: Finish Year | C5: =C2+C4 -> 2049
B6: The year that needs to be iqual to $0 is | C6: =C5+1 -> 2050
B8: Partner 1 age at start of Stage | C8: ='Income - Stage 1'!C7 -> 65
B9: Partner 1 age at END of Stage | C9: =C8+C4 -> 88
B11: Partner 2 age at stage of stage | C11: ='Income - Stage 1'!C8 -> 62
B12: Partner 2 age at END of Stage | C12: =C11+C4 -> 85
B14: Tax Rate (%) | C14: 0.15
B15: Fees % | C15: 0.011
B16: Inflation | C16: 0.03
B18: Portfolio | C18: Balanced | D18: "- this is a pull down menue that automatically fills in the Income % and Growth %"
B19: Portfolio Attributes
B20: income return (%) | C20: 0.035
B21: Growth (%) | C21: 0.045
B23: Calander Year | D23: =C2 -> 2026 | E23: =D23+1 -> 2027 | F23: =E23+1 -> 2028 | G23: =F23+1 -> 2029 | H23: =G23+1 -> 2030 | I23: =H23+1 -> 2031 | J23: =I23+1 -> 2032 | K23: =J23+1 -> 2033 | L23: =K23+1 -> 2034 | ... AI23: =AH23+1 -> 2057
B24: Year | D24: =C3 -> 1 | E24: =D24+1 -> 2 | F24: =E24+1 -> 3 | G24: =F24+1 -> 4 | H24: =G24+1 -> 5 | I24: =H24+1 -> 6 | J24: =I24+1 -> 7 | K24: =J24+1 -> 8 | L24: =K24+1 -> 9 | ... AI24: =AH24+1 -> 32
B25: Partner 1 age | D25: =C8 -> 65 | E25: =D25+1 -> 66 | F25: =E25+1 -> 67 | G25: =F25+1 -> 68 | H25: =G25+1 -> 69 | I25: =H25+1 -> 70 | J25: =I25+1 -> 71 | K25: =J25+1 -> 72 | L25: =K25+1 -> 73 | ... AI25: =AH25+1 -> 96
B26: Partner 2 age | D26: =C11 -> 62 | E26: =D26+1 -> 63 | F26: =E26+1 -> 64 | G26: =F26+1 -> 65 | H26: =G26+1 -> 66 | I26: =H26+1 -> 67 | J26: =I26+1 -> 68 | K26: =J26+1 -> 69 | L26: =K26+1 -> 70 | ... AI26: =AH26+1 -> 93
B29: open balance | D29: 115568.24 | E29: =D56 -> 113706.96 | F29: =E56 -> 111706.56 | G29: =F56 -> 109556.62 | H29: =G56 -> 107245.98 | I29: =H56 -> 104762.62 | J29: =I56 -> 102093.62 | K29: =J56 -> 99225.119 | L29: =K56 -> 96142.197 | ... AI29: =AH56 -> 3.6154603e-11
B30: income return (%) | D30: =C20 -> 0.035 | E30: =D30 -> 0.035 | F30: =E30 -> 0.035 | G30: =F30 -> 0.035 | H30: =G30 -> 0.035 | I30: =H30 -> 0.035 | J30: =I30 -> 0.035 | K30: =J30 -> 0.035 | L30: =K30 -> 0.035 | ... AI30: =AH30 -> 0.035
B31: income return ($) | D31: =D29*D30 -> 4044.8882 | E31: =E29*E30 -> 3979.7436 | F31: =F29*F30 -> 3909.7295 | G31: =G29*G30 -> 3834.4817 | H31: =H29*H30 -> 3753.6093 | I31: =I29*I30 -> 3666.6915 | J31: =J29*J30 -> 3573.2767 | K31: =K29*K30 -> 3472.8792 | ... AI31: =AI29*AI30 -> 1.2654111e-12
B32: Tax Rate (%) | D32: =C14 -> 0.15 | E32: =D32 -> 0.15 | F32: =E32 -> 0.15 | G32: =F32 -> 0.15 | H32: =G32 -> 0.15 | I32: =H32 -> 0.15 | J32: =I32 -> 0.15 | K32: =J32 -> 0.15 | L32: =K32 -> 0.15 | ... AI32: =AH32 -> 0.15
B33: Tax Rate ($) | D33: =IF((D31*D32)<0,0,(D31*D32)) -> 606.73323 | E33: =IF((E31*E32)<0,0,(E31*E32)) -> 596.96154 | F33: =IF((F31*F32)<0,0,(F31*F32)) -> 586.45942 | G33: =IF((G31*G32)<0,0,(G31*G32)) -> 575.17226 | H33: =IF((H31*H32)<0,0,(H31*H32)) -> 563.04139 | I33: =IF((I31*I32)<0,0,(I31*I32)) -> 550.00373 | J33: =IF((J31*J32)<0,0,(J31*J32)) -> 535.99151 | K33: =IF((K31*K32)<0,0,(K31*K32)) -> 520.93188 | ... AI33: =IF((AI31*AI32)<0,0,(AI31*AI32)) -> 1.8981166e-13
B34: Income after tax | D34: =IF((D31-D33)<0,0,(D31-D33)) -> 3438.155 | E34: =IF((E31-E33)<0,0,(E31-E33)) -> 3382.7821 | F34: =IF((F31-F33)<0,0,(F31-F33)) -> 3323.27 | G34: =IF((G31-G33)<0,0,(G31-G33)) -> 3259.3095 | H34: =IF((H31-H33)<0,0,(H31-H33)) -> 3190.5679 | I34: =IF((I31-I33)<0,0,(I31-I33)) -> 3116.6878 | J34: =IF((J31-J33)<0,0,(J31-J33)) -> 3037.2852 | K34: =IF((K31-K33)<0,0,(K31-K33)) -> 2951.9473 | ... AI34: =IF((AI31-AI33)<0,0,(AI31-AI33)) -> 1.0755994e-12
B36: Growth (%) | D36: =C21 -> 0.045 | E36: =D36 -> 0.045 | F36: =E36 -> 0.045 | G36: =F36 -> 0.045 | H36: =G36 -> 0.045 | I36: =H36 -> 0.045 | J36: =I36 -> 0.045 | K36: =J36 -> 0.045 | L36: =K36 -> 0.045 | ... AI36: =AH36 -> 0.045
B37: Growth ($) | D37: =IF((D36*D29)<0,0,(D36*D29)) -> 5200.5706 | E37: =IF((E36*E29)<0,0,(E36*E29)) -> 5116.8132 | F37: =IF((F36*F29)<0,0,(F36*F29)) -> 5026.795 | G37: =IF((G36*G29)<0,0,(G36*G29)) -> 4930.048 | H37: =IF((H36*H29)<0,0,(H36*H29)) -> 4826.069 | I37: =IF((I36*I29)<0,0,(I36*I29)) -> 4714.3177 | J37: =IF((J36*J29)<0,0,(J36*J29)) -> 4594.2129 | K37: =IF((K36*K29)<0,0,(K36*K29)) -> 4465.1304 | ... AI37: =IF((AI36*AI29)<0,0,(AI36*AI29)) -> 1.6269571e-12
B39: Closing Balance | D39: =D29+D34+D37 -> 124206.96 | E39: =E29+E34+E37 -> 122206.56 | F39: =F29+F34+F37 -> 120056.62 | G39: =G29+G34+G37 -> 117745.98 | H39: =H29+H34+H37 -> 115262.62 | I39: =I29+I34+I37 -> 112593.62 | J39: =J29+J34+J37 -> 109725.12 | K39: =K29+K34+K37 -> 106642.2 | ... AI39: =AI29+AI34+AI37 -> 3.8857159e-11
B41: holiday costs
B42: Weeks per year | C42: 2
B43: Days away | C43: =C42*7 -> 14
B45: Accomodation cost per night | C45: 350
B46: Transport cost per day | C46: 100
B47: Food cost per day | C47: 150
B48: Fun cost per day | C48: 150
B49: No of Airfairs | C49: 0
B50: Tickets per person | C50: 0
B52: Hollding Costs - Total | C52: =(C43*(C45+C46+C47+C48)+(C49*C50)) -> 10500
...

Sheet International Holidays
B1: Car for Partner 2
B2: Calander Year at Stage | C2: ='Income - Stage 1'!C3 -> 2026
B3: Start year | C3: ='Income - Stage 1'!C4 -> 1
B4: Stage length | C4: 23
B5: Finish Year | C5: =C2+C4 -> 2049
B6: The year that needs to be iqual to $0 is | C6: =C5+1 -> 2050
B8: Partner 1 age at start of Stage | C8: ='Income - Stage 1'!C7 -> 65
B9: Partner 1 age at END of Stage | C9: =C8+C4 -> 88
B11: Partner 2 age at stage of stage | C11: ='Income - Stage 1'!C8 -> 62
B12: Partner 2 age at END of Stage | C12: =C11+C4 -> 85
B14: Tax Rate (%) | C14: 0.15
B15: Fees % | C15: 0.011
B16: Inflation | C16: 0.03
B18: Portfolio | C18: Balanced | D18: "- this is a pull down menue that automatically fills in the Income % and Growth %"
B19: Portfolio Attributes
B20: income return (%) | C20: 0.035
B21: Growth (%) | C21: 0.045
B23: Calander Year | D23: =C2 -> 2026 | E23: =D23+1 -> 2027 | F23: =E23+1 -> 2028 | G23: =F23+1 -> 2029 | H23: =G23+1 -> 2030 | I23: =H23+1 -> 2031 | J23: =I23+1 -> 2032 | K23: =J23+1 -> 2033 | L23: =K23+1 -> 2034 | ... AI23: =AH23+1 -> 2057
B24: Year | D24: =C3 -> 1 | E24: =D24+1 -> 2 | F24: =E24+1 -> 3 | G24: =F24+1 -> 4 | H24: =G24+1 -> 5 | I24: =H24+1 -> 6 | J24: =I24+1 -> 7 | K24: =J24+1 -> 8 | L24: =K24+1 -> 9 | ... AI24: =AH24+1 -> 32
B25: Partner 1 age | D25: =C8 -> 65 | E25: =D25+1 -> 66 | F25: =E25+1 -> 67 | G25: =F25+1 -> 68 | H25: =G25+1 -> 69 | I25: =H25+1 -> 70 | J25: =I25+1 -> 71 | K25: =J25+1 -> 72 | L25: =K25+1 -> 73 | ... AI25: =AH25+1 -> 96
B26: Partner 2 age | D26: =C11 -> 62 | E26: =D26+1 -> 63 | F26: =E26+1 -> 64 | G26: =F26+1 -> 65 | H26: =G26+1 -> 66 | I26: =H26+1 -> 67 | J26: =I26+1 -> 68 | K26: =J26+1 -> 69 | L26: =K26+1 -> 70 | ... AI26: =AH26+1 -> 93
B29: open balance | D29: 142534.16 | E29: =D56 -> 140238.58 | F29: =E56 -> 137771.42 | G29: =F56 -> 135119.83 | H29: =G56 -> 132270.04 | I29: =H56 -> 129207.23 | J29: =I56 -> 125915.47 | K29: =J56 -> 122377.65 | L29: =K56 -> 118575.38 | ... AI29: =AH56 -> 2.4705645e-10
B30: income return (%) | D30: =C20 -> 0.035 | E30: =D30 -> 0.035 | F30: =E30 -> 0.035 | G30: =F30 -> 0.035 | H30: =G30 -> 0.035 | I30: =H30 -> 0.035 | J30: =I30 -> 0.035 | K30: =J30 -> 0.035 | L30: =K30 -> 0.035 | ... AI30: =AH30 -> 0.035
B31: income return ($) | D31: =D29*D30 -> 4988.6955 | E31: =E29*E30 -> 4908.3505 | F31: =F29*F30 -> 4821.9997 | G31: =G29*G30 -> 4729.1941 | H31: =H29*H30 -> 4629.4514 | I31: =I29*I30 -> 4522.2529 | J31: =J29*J30 -> 4407.0413 | K31: =K29*K30 -> 4283.2176 | ... AI31: =AI29*AI30 -> 8.6469758e-12
B32: Tax Rate (%) | D32: =C14 -> 0.15 | E32: =D32 -> 0.15 | F32: =E32 -> 0.15 | G32: =F32 -> 0.15 | H32: =G32 -> 0.15 | I32: =H32 -> 0.15 | J32: =I32 -> 0.15 | K32: =J32 -> 0.15 | L32: =K32 -> 0.15 | ... AI32: =AH32 -> 0.15
B33: Tax Rate ($) | D33: =IF((D31*D32)<0,0,(D31*D32)) -> 748.30432 | E33: =IF((E31*E32)<0,0,(E31*E32)) -> 736.25257 | F33: =IF((F31*F32)<0,0,(F31*F32)) -> 723.29995 | G33: =IF((G31*G32)<0,0,(G31*G32)) -> 709.37912 | H33: =IF((H31*H32)<0,0,(H31*H32)) -> 694.41771 | I33: =IF((I31*I32)<0,0,(I31*I32)) -> 678.33794 | J33: =IF((J31*J32)<0,0,(J31*J32)) -> 661.0562 | K33: =IF((K31*K32)<0,0,(K31*K32)) -> 642.48265 | ... AI33: =IF((AI31*AI32)<0,0,(AI31*AI32)) -> 1.2970464e-12
B34: Income after tax | D34: =IF((D31-D33)<0,0,(D31-D33)) -> 4240.3912 | E34: =IF((E31-E33)<0,0,(E31-E33)) -> 4172.0979 | F34: =IF((F31-F33)<0,0,(F31-F33)) -> 4098.6997 | G34: =IF((G31-G33)<0,0,(G31-G33)) -> 4019.815 | H34: =IF((H31-H33)<0,0,(H31-H33)) -> 3935.0337 | I34: =IF((I31-I33)<0,0,(I31-I33)) -> 3843.915 | J34: =IF((J31-J33)<0,0,(J31-J33)) -> 3745.9851 | K34: =IF((K31-K33)<0,0,(K31-K33)) -> 3640.735 | ... AI34: =IF((AI31-AI33)<0,0,(AI31-AI33)) -> 7.3499294e-12
B36: Growth (%) | D36: =C21 -> 0.045 | E36: =D36 -> 0.045 | F36: =E36 -> 0.045 | G36: =F36 -> 0.045 | H36: =G36 -> 0.045 | I36: =H36 -> 0.045 | J36: =I36 -> 0.045 | K36: =J36 -> 0.045 | L36: =K36 -> 0.045 | ... AI36: =AH36 -> 0.045
B37: Growth ($) | D37: =IF((D36*D29)<0,0,(D36*D29)) -> 6414.0371 | E37: =IF((E36*E29)<0,0,(E36*E29)) -> 6310.7363 | F37: =IF((F36*F29)<0,0,(F36*F29)) -> 6199.7139 | G37: =IF((G36*G29)<0,0,(G36*G29)) -> 6080.3925 | H37: =IF((H36*H29)<0,0,(H36*H29)) -> 5952.1518 | I37: =IF((I36*I29)<0,0,(I36*I29)) -> 5814.3252 | J37: =IF((J36*J29)<0,0,(J36*J29)) -> 5666.196 | K37: =IF((K36*K29)<0,0,(K36*K29)) -> 5506.9941 | ... AI37: =IF((AI36*AI29)<0,0,(AI36*AI29)) -> 1.111754e-11
B39: Closing Balance | D39: =D29+D34+D37 -> 153188.58 | E39: =E29+E34+E37 -> 150721.42 | F39: =F29+F34+F37 -> 148069.83 | G39: =G29+G34+G37 -> 145220.04 | H39: =H29+H34+H37 -> 142157.23 | I39: =I29+I34+I37 -> 138865.47 | J39: =J29+J34+J37 -> 135327.65 | K39: =K29+K34+K37 -> 131525.38 | ... AI39: =AI29+AI34+AI37 -> 2.6552392e-10
B41: holiday costs
B42: Weeks per year | C42: 3
B43: Days away | C43: =C42*7 -> 21
B45: Accomodation cost per night | C45: 350
B46: Transport cost per day | C46: 150
B47: Food cost per day | C47: 200
B48: Fun cost per day | C48: 200
B49: No of Airfairs | C49: 2
B50: Tickets per person | C50: 3500
B52: Hollding Costs - Total | C52: =(C43*(C45+C46+C47+C48)+(C49*C50)) -> 25900
...

Sheet Travel to see Parents overseas

Sheet Travel to see others

Sheet Medical Expenses
